Workbook

Sheet Sheet1
A2: Cash Up Sheet
B4: 41897 | C4: =B4+1 -> 41898 | D4: =C4+1 -> 41899 | E4: =D4+1 -> 41900 | F4: =E4+1 -> 41901 | G4: =F4+1 -> 41902 | H4: =G4+1 -> 41903 | I4: =H4+1 -> 41904 | J4: =I4+1 -> 41905 | ... Q4: =P4+1 -> 41912
A5: TILL FLOAT
A6: 0.01
A7: 0.05
A8: 0.2
A9: 0.5
A10: 1
A11: 2
A12: 5
A13: 10
A14: 20
A15: Total | B15: =SUM(B6:B14) -> 0 | C15: =SUM(C6:C14) -> 0 | D15: =SUM(D6:D14) -> 0 | E15: =SUM(E6:E14) -> 0 | F15: =SUM(F6:F14) -> 0 | G15: =SUM(G6:G14) -> 0 | H15: =SUM(H6:H14) -> 0 | I15: =SUM(I6:I14) -> 0 | ... Q15: =SUM(Q6:Q14) -> 0
A17: TAKINGS
A18: 0.01
A19: 0.05
A20: 0.2
A21: 0.5
A22: 1
A23: 2
A24: 5
A25: 10
A26: 20
A27: Total | B27: =SUM(B18:B26) -> 0 | C27: =SUM(C18:C26) -> 0 | D27: =SUM(D18:D26) -> 0 | E27: =SUM(E18:E26) -> 0 | F27: =SUM(F18:F26) -> 0 | G27: =SUM(G18:G26) -> 0 | H27: =SUM(H18:H26) -> 0 | I27: =SUM(I18:I26) -> 0 | ... Q27: =SUM(Q18:Q26) -> 0
A29: SAFE
A30: 0.01
A31: 0.05
A32: 0.2
A33: 0.5
A34: 1
A35: 2
A36: 5
A37: 10
A38: 20
A39: Total | B39: =SUM(B35:B38) -> 0 | C39: =SUM(C35:C38) -> 0 | D39: =SUM(D35:D38) -> 0 | E39: =SUM(E35:E38) -> 0 | F39: =SUM(F35:F38) -> 0 | G39: =SUM(G35:G38) -> 0 | H39: =SUM(H35:H38) -> 0 | I39: =SUM(I35:I38) -> 0 | ... Q39: =SUM(Q35:Q38) -> 0
A41: RECEIPTS (Dockets Attached)
A42: Receipt 1
A43: Receipt 2
A44: Receipt 3
A45: Receipt 4
...

Sheet MON
A3: COMMENTS
A7: TILL FLOAT (No. of coins/notes) | B7: MONDAY
A8: 0.01
A9: 0.02
A10: 0.05
A11: 0.1
A12: 0.2
A13: 0.5
A14: 1
A15: 2
A16: 5
A17: 10
A18: 20
A19: Total | B19: =SUM((B8*A8),(B9*A9),(B10*A10),(B11*A11),(B12*A12),(B13*A13),(B14*A14),(B15*A15),(B16*A16),(B17*A17),(B18*A18)) -> 0
A20: TILL VARIANCE Should be 0! | B20: =500-B19 -> 500
A22: TAKINGS (No. of coins/notes) | B22: =B7 -> MONDAY
A23: 0.01
A24: 0.02
A25: 0.05
A26: 0.1
A27: 0.2
A28: 0.5
A29: 1
A30: 2
A31: 5
A32: 10
A33: 20
A34: Total | B34: =SUM((B23*A23),(B24*A24),(B25*A25),(B26*A26),(B27*A27),(B28*A28),(B29*A29),(B30*A30),(B31*A31),(B32*A32),(B33*A33)) -> 0
A36: SAFE (No. of coins/notes) | B36: =B7 -> MONDAY
A37: 0.01
A38: 0.02
A39: 0.05
A40: 0.1
A41: 0.2
A42: 0.5
A43: 1
A44: 2
A45: 5
A46: 10
A47: 20
...

Sheet TUES
A3: COMMENTS
A7: TILL FLOAT (No. of coins/notes) | B7: TUESDAY
A8: 0.01
A9: 0.02
A10: 0.05
A11: 0.1
A12: 0.2
A13: 0.5
A14: 1
A15: 2
A16: 5
A17: 10
A18: 20
A19: Total | B19: =SUM((B8*A8),(B9*A9),(B10*A10),(B11*A11),(B12*A12),(B13*A13),(B14*A14),(B15*A15),(B16*A16),(B17*A17),(B18*A18)) -> 0
A20: TILL VARIANCE Should be 0! | B20: =500-B19 -> 500
A22: TAKINGS (No. of coins/notes) | B22: =B7 -> TUESDAY
A23: 0.01
A24: 0.02
A25: 0.05
A26: 0.1
A27: 0.2
A28: 0.5
A29: 1
A30: 2
A31: 5
A32: 10
A33: 20
A34: Total | B34: =SUM((B23*A23),(B24*A24),(B25*A25),(B26*A26),(B27*A27),(B28*A28),(B29*A29),(B30*A30),(B31*A31),(B32*A32),(B33*A33)) -> 0
A36: SAFE (No. of coins/notes) | B36: =B7 -> TUESDAY
A37: 0.01
A38: 0.02
A39: 0.05
A40: 0.1
A41: 0.2
A42: 0.5
A43: 1
A44: 2
A45: 5
A46: 10
A47: 20
...

Sheet WED
A3: COMMENTS
A7: TILL FLOAT (No. of coins/notes) | B7: WEDNESDAY
A8: 0.01
A9: 0.02
A10: 0.05
A11: 0.1
A12: 0.2
A13: 0.5
A14: 1
A15: 2
A16: 5
A17: 10
A18: 20
A19: Total | B19: =SUM((B8*A8),(B9*A9),(B10*A10),(B11*A11),(B12*A12),(B13*A13),(B14*A14),(B15*A15),(B16*A16),(B17*A17),(B18*A18)) -> 0
A20: TILL VARIANCE Should be 0! | B20: =500-B19 -> 500
A22: TAKINGS (No. of coins/notes) | B22: =B7 -> WEDNESDAY
A23: 0.01
A24: 0.02
A25: 0.05
A26: 0.1
A27: 0.2
A28: 0.5
A29: 1
A30: 2
A31: 5
A32: 10
A33: 20
A34: Total | B34: =SUM((B23*A23),(B24*A24),(B25*A25),(B26*A26),(B27*A27),(B28*A28),(B29*A29),(B30*A30),(B31*A31),(B32*A32),(B33*A33)) -> 0
A36: SAFE (No. of coins/notes) | B36: =B7 -> WEDNESDAY
A37: 0.01
A38: 0.02
A39: 0.05
A40: 0.1
A41: 0.2
A42: 0.5
A43: 1
A44: 2
A45: 5
A46: 10
A47: 20
...

Sheet THUR
A3: COMMENTS
A7: TILL FLOAT (No. of coins/notes) | B7: THURSDAY
A8: 0.01
A9: 0.02
A10: 0.05
A11: 0.1
A12: 0.2
A13: 0.5
A14: 1
A15: 2
A16: 5
A17: 10
A18: 20
A19: Total | B19: =SUM((B8*A8),(B9*A9),(B10*A10),(B11*A11),(B12*A12),(B13*A13),(B14*A14),(B15*A15),(B16*A16),(B17*A17),(B18*A18)) -> 0
A20: TILL VARIANCE Should be 0! | B20: =500-B19 -> 500
A22: TAKINGS (No. of coins/notes) | B22: =B7 -> THURSDAY
A23: 0.01
A24: 0.02
A25: 0.05
A26: 0.1
A27: 0.2
A28: 0.5
A29: 1
A30: 2
A31: 5
A32: 10
A33: 20
A34: Total | B34: =SUM((B23*A23),(B24*A24),(B25*A25),(B26*A26),(B27*A27),(B28*A28),(B29*A29),(B30*A30),(B31*A31),(B32*A32),(B33*A33)) -> 0
A36: SAFE (No. of coins/notes) | B36: =B7 -> THURSDAY
A37: 0.01
A38: 0.02
A39: 0.05
A40: 0.1
A41: 0.2
A42: 0.5
A43: 1
A44: 2
A45: 5
A46: 10
A47: 20
...

Sheet FRI
A3: COMMENTS
A7: TILL FLOAT (No. of coins/notes) | B7: FRIDAY
A8: 0.01
A9: 0.02
A10: 0.05
A11: 0.1
A12: 0.2
A13: 0.5
A14: 1
A15: 2
A16: 5
A17: 10
A18: 20
A19: Total | B19: =SUM((B8*A8),(B9*A9),(B10*A10),(B11*A11),(B12*A12),(B13*A13),(B14*A14),(B15*A15),(B16*A16),(B17*A17),(B18*A18)) -> 0
A20: TILL VARIANCE Should be 0! | B20: =500-B19 -> 500
A22: TAKINGS (No. of coins/notes) | B22: =B7 -> FRIDAY
A23: 0.01
A24: 0.02
A25: 0.05
A26: 0.1
A27: 0.2
A28: 0.5
A29: 1
A30: 2
A31: 5
A32: 10
A33: 20
A34: Total | B34: =SUM((B23*A23),(B24*A24),(B25*A25),(B26*A26),(B27*A27),(B28*A28),(B29*A29),(B30*A30),(B31*A31),(B32*A32),(B33*A33)) -> 0
A36: SAFE (No. of coins/notes) | B36: =B7 -> FRIDAY
A37: 0.01
A38: 0.02
A39: 0.05
A40: 0.1
A41: 0.2
A42: 0.5
A43: 1
A44: 2
A45: 5
A46: 10
A47: 20
...

Sheet SAT
A3: COMMENTS
A7: TILL FLOAT (No. of coins/notes) | B7: SATURDAY
A8: 0.01
A9: 0.02
A10: 0.05
A11: 0.1
A12: 0.2
A13: 0.5
A14: 1
A15: 2
A16: 5
A17: 10
A18: 20
A19: Total | B19: =SUM((B8*A8),(B9*A9),(B10*A10),(B11*A11),(B12*A12),(B13*A13),(B14*A14),(B15*A15),(B16*A16),(B17*A17),(B18*A18)) -> 0
A20: TILL VARIANCE Should be 0! | B20: =500-B19 -> 500
A22: TAKINGS (No. of coins/notes) | B22: =B7 -> SATURDAY
A23: 0.01
A24: 0.02
A25: 0.05
A26: 0.1
A27: 0.2
A28: 0.5
A29: 1
A30: 2
A31: 5
A32: 10
A33: 20
A34: Total | B34: =SUM((B23*A23),(B24*A24),(B25*A25),(B26*A26),(B27*A27),(B28*A28),(B29*A29),(B30*A30),(B31*A31),(B32*A32),(B33*A33)) -> 0
A36: SAFE (No. of coins/notes) | B36: =B7 -> SATURDAY
A37: 0.01
A38: 0.02
A39: 0.05
A40: 0.1
A41: 0.2
A42: 0.5
A43: 1
A44: 2
A45: 5
A46: 10
A47: 20
...

Sheet SUN
A3: COMMENTS
A7: TILL FLOAT (No. of coins/notes) | B7: SUNDAY
A8: 0.01
A9: 0.02
A10: 0.05
A11: 0.1
A12: 0.2
A13: 0.5
A14: 1
A15: 2
A16: 5
A17: 10
A18: 20
A19: Total | B19: =SUM((B8*A8),(B9*A9),(B10*A10),(B11*A11),(B12*A12),(B13*A13),(B14*A14),(B15*A15),(B16*A16),(B17*A17),(B18*A18)) -> 0
A20: TILL VARIANCE Should be 0! | B20: =500-B19 -> 500
A22: TAKINGS (No. of coins/notes) | B22: =B7 -> SUNDAY
A23: 0.01
A24: 0.02
A25: 0.05
A26: 0.1
A27: 0.2
A28: 0.5
A29: 1
A30: 2
A31: 5
A32: 10
A33: 20
A34: Total | B34: =SUM((B23*A23),(B24*A24),(B25*A25),(B26*A26),(B27*A27),(B28*A28),(B29*A29),(B30*A30),(B31*A31),(B32*A32),(B33*A33)) -> 0
A36: SAFE (No. of coins/notes) | B36: =B7 -> SUNDAY
A37: 0.01
A38: 0.02
A39: 0.05
A40: 0.1
A41: 0.2
A42: 0.5
A43: 1
A44: 2
A45: 5
A46: 10
A47: 20
...

Sheet WEEKBEGDATE
A3: =MON!A7 -> TILL FLOAT (No. of coins/notes) | B3: =MON!B7 -> MONDAY | C3: =TUES!B7 -> TUESDAY | D3: =WED!B7 -> WEDNESDAY | E3: =THUR!B7 -> THURSDAY | F3: =FRI!B7 -> FRIDAY | G3: =SAT!B7 -> SATURDAY | H3: =SUN!B7 -> SUNDAY | I3: TOTAL
A4: =MON!A8 -> 0.01 | B4: =MON!B8 -> 0 | C4: =TUES!B8 -> 0 | D4: =WED!B8 -> 0 | E4: =THUR!B8 -> 0 | F4: =FRI!B8 -> 0 | G4: =SAT!B8 -> 0 | H4: =SUN!B8 -> 0 | I4: =SUM(B4:H4) -> 0
A5: =MON!A9 -> 0.02 | B5: =MON!B9 -> 0 | C5: =TUES!B9 -> 0 | D5: =WED!B9 -> 0 | E5: =THUR!B9 -> 0 | F5: =FRI!B9 -> 0 | G5: =SAT!B9 -> 0 | H5: =SUN!B9 -> 0 | I5: =SUM(B5:H5) -> 0
A6: =MON!A10 -> 0.05 | B6: =MON!B10 -> 0 | C6: =TUES!B10 -> 0 | D6: =WED!B10 -> 0 | E6: =THUR!B10 -> 0 | F6: =FRI!B10 -> 0 | G6: =SAT!B10 -> 0 | H6: =SUN!B10 -> 0 | I6: =SUM(B6:H6) -> 0
A7: =MON!A11 -> 0.1 | B7: =MON!B11 -> 0 | C7: =TUES!B11 -> 0 | D7: =WED!B11 -> 0 | E7: =THUR!B11 -> 0 | F7: =FRI!B11 -> 0 | G7: =SAT!B11 -> 0 | H7: =SUN!B11 -> 0 | I7: =SUM(B7:H7) -> 0
A8: =MON!A12 -> 0.2 | B8: =MON!B12 -> 0 | C8: =TUES!B12 -> 0 | D8: =WED!B12 -> 0 | E8: =THUR!B12 -> 0 | F8: =FRI!B12 -> 0 | G8: =SAT!B12 -> 0 | H8: =SUN!B12 -> 0 | I8: =SUM(B8:H8) -> 0
A9: =MON!A13 -> 0.5 | B9: =MON!B13 -> 0 | C9: =TUES!B13 -> 0 | D9: =WED!B13 -> 0 | E9: =THUR!B13 -> 0 | F9: =FRI!B13 -> 0 | G9: =SAT!B13 -> 0 | H9: =SUN!B13 -> 0 | I9: =SUM(B9:H9) -> 0
A10: =MON!A14 -> 1 | B10: =MON!B14 -> 0 | C10: =TUES!B14 -> 0 | D10: =WED!B14 -> 0 | E10: =THUR!B14 -> 0 | F10: =FRI!B14 -> 0 | G10: =SAT!B14 -> 0 | H10: =SUN!B14 -> 0 | I10: =SUM(B10:H10) -> 0
A11: =MON!A15 -> 2 | B11: =MON!B15 -> 0 | C11: =TUES!B15 -> 0 | D11: =WED!B15 -> 0 | E11: =THUR!B15 -> 0 | F11: =FRI!B15 -> 0 | G11: =SAT!B15 -> 0 | H11: =SUN!B15 -> 0 | I11: =SUM(B11:H11) -> 0
A12: =MON!A16 -> 5 | B12: =MON!B16 -> 0 | C12: =TUES!B16 -> 0 | D12: =WED!B16 -> 0 | E12: =THUR!B16 -> 0 | F12: =FRI!B16 -> 0 | G12: =SAT!B16 -> 0 | H12: =SUN!B16 -> 0 | I12: =SUM(B12:H12) -> 0
A13: =MON!A17 -> 10 | B13: =MON!B17 -> 0 | C13: =TUES!B17 -> 0 | D13: =WED!B17 -> 0 | E13: =THUR!B17 -> 0 | F13: =FRI!B17 -> 0 | G13: =SAT!B17 -> 0 | H13: =SUN!B17 -> 0 | I13: =SUM(B13:H13) -> 0
A14: =MON!A18 -> 20 | B14: =MON!B18 -> 0 | C14: =TUES!B18 -> 0 | D14: =WED!B18 -> 0 | E14: =THUR!B18 -> 0 | F14: =FRI!B18 -> 0 | G14: =SAT!B18 -> 0 | H14: =SUN!B18 -> 0 | I14: =SUM(B14:H14) -> 0
A15: =MON!A19 -> Total | B15: =MON!B19 -> 0 | C15: =TUES!B19 -> 0 | D15: =WED!B19 -> 0 | E15: =THUR!B19 -> 0 | F15: =FRI!B19 -> 0 | G15: =SAT!B19 -> 0 | H15: =SUN!B19 -> 0 | I15: =SUM(I4:I14) -> 0
A16: =IF(I16>10,"THIS SHOULD BE ZERO","") -> THIS SHOULD BE ZERO | B16: =MON!B20 -> 500 | C16: =TUES!B20 -> 500 | D16: =WED!B20 -> 500 | E16: =THUR!B20 -> 500 | F16: =FRI!B20 -> 500 | G16: =SAT!B20 -> 500 | H16: =SUN!B20 -> 500 | I16: =SUM(B16:H16) -> 3500
A18: =MON!A22 -> TAKINGS (No. of coins/notes) | B18: =MON!B22 -> MONDAY | C18: =TUES!B22 -> TUESDAY | D18: =WED!B22 -> WEDNESDAY | E18: =THUR!B22 -> THURSDAY | F18: =FRI!B22 -> FRIDAY | G18: =SAT!B22 -> SATURDAY | H18: =SUN!B22 -> SUNDAY | I18: =I3 -> TOTAL
A19: =MON!A23 -> 0.01 | B19: =MON!B23 -> 0 | C19: =TUES!B23 -> 0 | D19: =WED!B23 -> 0 | E19: =THUR!B23 -> 0 | F19: =FRI!B23 -> 0 | G19: =SAT!B23 -> 0 | H19: =SUN!B23 -> 0 | I19: =SUM(B19:H19) -> 0
A20: =MON!A24 -> 0.02 | B20: =MON!B24 -> 0 | C20: =TUES!B24 -> 0 | D20: =WED!B24 -> 0 | E20: =THUR!B24 -> 0 | F20: =FRI!B24 -> 0 | G20: =SAT!B24 -> 0 | H20: =SUN!B24 -> 0 | I20: =SUM(B20:H20) -> 0
A21: =MON!A25 -> 0.05 | B21: =MON!B25 -> 0 | C21: =TUES!B25 -> 0 | D21: =WED!B25 -> 0 | E21: =THUR!B25 -> 0 | F21: =FRI!B25 -> 0 | G21: =SAT!B25 -> 0 | H21: =SUN!B25 -> 0 | I21: =SUM(B21:H21) -> 0
A22: =MON!A26 -> 0.1 | B22: =MON!B26 -> 0 | C22: =TUES!B26 -> 0 | D22: =WED!B26 -> 0 | E22: =THUR!B26 -> 0 | F22: =FRI!B26 -> 0 | G22: =SAT!B26 -> 0 | H22: =SUN!B26 -> 0 | I22: =SUM(B22:H22) -> 0
A23: =MON!A27 -> 0.2 | B23: =MON!B27 -> 0 | C23: =TUES!B27 -> 0 | D23: =WED!B27 -> 0 | E23: =THUR!B27 -> 0 | F23: =FRI!B27 -> 0 | G23: =SAT!B27 -> 0 | H23: =SUN!B27 -> 0 | I23: =SUM(B23:H23) -> 0
A24: =MON!A28 -> 0.5 | B24: =MON!B28 -> 0 | C24: =TUES!B28 -> 0 | D24: =WED!B28 -> 0 | E24: =THUR!B28 -> 0 | F24: =FRI!B28 -> 0 | G24: =SAT!B28 -> 0 | H24: =SUN!B28 -> 0 | I24: =SUM(B24:H24) -> 0
A25: =MON!A29 -> 1 | B25: =MON!B29 -> 0 | C25: =TUES!B29 -> 0 | D25: =WED!B29 -> 0 | E25: =THUR!B29 -> 0 | F25: =FRI!B29 -> 0 | G25: =SAT!B29 -> 0 | H25: =SUN!B29 -> 0 | I25: =SUM(B25:H25) -> 0
A26: =MON!A30 -> 2 | B26: =MON!B30 -> 0 | C26: =TUES!B30 -> 0 | D26: =WED!B30 -> 0 | E26: =THUR!B30 -> 0 | F26: =FRI!B30 -> 0 | G26: =SAT!B30 -> 0 | H26: =SUN!B30 -> 0 | I26: =SUM(B26:H26) -> 0
A27: =MON!A31 -> 5 | B27: =MON!B31 -> 0 | C27: =TUES!B31 -> 0 | D27: =WED!B31 -> 0 | E27: =THUR!B31 -> 0 | F27: =FRI!B31 -> 0 | G27: =SAT!B31 -> 0 | H27: =SUN!B31 -> 0 | I27: =SUM(B27:H27) -> 0
A28: =MON!A32 -> 10 | B28: =MON!B32 -> 0 | C28: =TUES!B32 -> 0 | D28: =WED!B32 -> 0 | E28: =THUR!B32 -> 0 | F28: =FRI!B32 -> 0 | G28: =SAT!B32 -> 0 | H28: =SUN!B32 -> 0 | I28: =SUM(B28:H28) -> 0
A29: =MON!A33 -> 20 | B29: =MON!B33 -> 0 | C29: =TUES!B33 -> 0 | D29: =WED!B33 -> 0 | E29: =THUR!B33 -> 0 | F29: =FRI!B33 -> 0 | G29: =SAT!B33 -> 0 | H29: =SUN!B33 -> 0 | I29: =SUM(B29:H29) -> 0
A30: =MON!A34 -> Total | B30: =MON!B34 -> 0 | C30: =TUES!B34 -> 0 | D30: =WED!B34 -> 0 | E30: =THUR!B34 -> 0 | F30: =FRI!B34 -> 0 | G30: =SAT!B34 -> 0 | H30: =SUN!B34 -> 0 | I30: =SUM(I19:I29) -> 0
A32: =MON!A36 -> SAFE (No. of coins/notes) | B32: =MON!B36 -> MONDAY | C32: =TUES!B36 -> TUESDAY | D32: =WED!B36 -> WEDNESDAY | E32: =THUR!B36 -> THURSDAY | F32: =FRI!B36 -> FRIDAY | G32: =SAT!B36 -> SATURDAY | H32: =SUN!B36 -> SUNDAY | I32: =I3 -> TOTAL
A33: =MON!A37 -> 0.01 | B33: =MON!B37 -> 0 | C33: =TUES!B37 -> 0 | D33: =WED!B37 -> 0 | E33: =THUR!B37 -> 0 | F33: =FRI!B37 -> 0 | G33: =SAT!B37 -> 0 | H33: =SUN!B37 -> 0 | I33: =SUM(B33:H33) -> 0
A34: =MON!A38 -> 0.02 | B34: =MON!B38 -> 0 | C34: =TUES!B38 -> 0 | D34: =WED!B38 -> 0 | E34: =THUR!B38 -> 0 | F34: =FRI!B38 -> 0 | G34: =SAT!B38 -> 0 | H34: =SUN!B38 -> 0 | I34: =SUM(B34:H34) -> 0
A35: =MON!A39 -> 0.05 | B35: =MON!B39 -> 0 | C35: =TUES!B39 -> 0 | D35: =WED!B39 -> 0 | E35: =THUR!B39 -> 0 | F35: =FRI!B39 -> 0 | G35: =SAT!B39 -> 0 | H35: =SUN!B39 -> 0 | I35: =SUM(B35:H35) -> 0
A36: =MON!A40 -> 0.1 | B36: =MON!B40 -> 0 | C36: =TUES!B40 -> 0 | D36: =WED!B40 -> 0 | E36: =THUR!B40 -> 0 | F36: =FRI!B40 -> 0 | G36: =SAT!B40 -> 0 | H36: =SUN!B40 -> 0 | I36: =SUM(B36:H36) -> 0
A37: =MON!A41 -> 0.2 | B37: =MON!B41 -> 0 | C37: =TUES!B41 -> 0 | D37: =WED!B41 -> 0 | E37: =THUR!B41 -> 0 | F37: =FRI!B41 -> 0 | G37: =SAT!B41 -> 0 | H37: =SUN!B41 -> 0 | I37: =SUM(B37:H37) -> 0
A38: =MON!A42 -> 0.5 | B38: =MON!B42 -> 0 | C38: =TUES!B42 -> 0 | D38: =WED!B42 -> 0 | E38: =THUR!B42 -> 0 | F38: =FRI!B42 -> 0 | G38: =SAT!B42 -> 0 | H38: =SUN!B42 -> 0 | I38: =SUM(B38:H38) -> 0
A39: =MON!A43 -> 1 | B39: =MON!B43 -> 0 | C39: =TUES!B43 -> 0 | D39: =WED!B43 -> 0 | E39: =THUR!B43 -> 0 | F39: =FRI!B43 -> 0 | G39: =SAT!B43 -> 0 | H39: =SUN!B43 -> 0 | I39: =SUM(B39:H39) -> 0
A40: =MON!A44 -> 2 | B40: =MON!B44 -> 0 | C40: =TUES!B44 -> 0 | D40: =WED!B44 -> 0 | E40: =THUR!B44 -> 0 | F40: =FRI!B44 -> 0 | G40: =SAT!B44 -> 0 | H40: =SUN!B44 -> 0 | I40: =SUM(B40:H40) -> 0
A41: =MON!A45 -> 5 | B41: =MON!B45 -> 0 | C41: =TUES!B45 -> 0 | D41: =WED!B45 -> 0 | E41: =THUR!B45 -> 0 | F41: =FRI!B45 -> 0 | G41: =SAT!B45 -> 0 | H41: =SUN!B45 -> 0 | I41: =SUM(B41:H41) -> 0
A42: =MON!A46 -> 10 | B42: =MON!B46 -> 0 | C42: =TUES!B46 -> 0 | D42: =WED!B46 -> 0 | E42: =THUR!B46 -> 0 | F42: =FRI!B46 -> 0 | G42: =SAT!B46 -> 0 | H42: =SUN!B46 -> 0 | I42: =SUM(B42:H42) -> 0
A43: =MON!A47 -> 20 | B43: =MON!B47 -> 0 | C43: =TUES!B47 -> 0 | D43: =WED!B47 -> 0 | E43: =THUR!B47 -> 0 | F43: =FRI!B47 -> 0 | G43: =SAT!B47 -> 0 | H43: =SUN!B47 -> 0 | I43: =SUM(B43:H43) -> 0
A44: =MON!A48 -> Total | B44: =MON!B48 -> 0 | C44: =TUES!B48 -> 0 | D44: =WED!B48 -> 0 | E44: =THUR!B48 -> 0 | F44: =FRI!B48 -> 0 | G44: =SAT!B48 -> 0 | H44: =SUN!B48 -> 0 | I44: =SUM(I33:I43) -> 0
...
